Workbook

Sheet Raw_Data
A1: Order ID | B1: Order Date | C1: Customer | D1: Region | E1: Category | F1: Product | G1: Quantity | H1: Sales | I1: Discount | J1: Profit
A2: ORD001 | B2: 46190 | C2: Rahul | D2: North | E2: Electronics | F2: Mouse | G2: 2 | H2: 1900 | I2: 0.05 | J2: 197.07
A3: ORD002 | B3: 46053 | C3: Fatima | D3: North | E3: Furniture | F3: Desk Lamp | G3: 4 | H3: 7200 | I3: 0 | J3: 612.47
A4: ORD003 | B4: 46082 | C4: Arjun | D4: North | E4: Furniture | F4: Bookshelf | G4: 2 | H4: 11900 | I4: 0.15 | J4: 1397.95
A5: ORD004 | B5: 46177 | C5: Priya | D5: North | E5: Electronics | F5: Monitor | G5: 4 | H5: 54000 | I5: 0.1 | J5: 6870.86
A6: ORD005 | B6: 46082 | C6: Sneha | D6: south | E6: Electronics | F6: Smartphone | G6: 1 | H6: 27200 | I6: 0.15 | J6: 2623.22
A7: ORD006 | B7: 46115 | C7: Rohan | D7: East | E7: Electronics | F7: Laptop | G7: 4 | H7: 220000 | I7: 0 | J7: 53994.53
A8: ORD007 | B8: 46123 | C8: Rahul | D8: East | E8: Furniture | F8: Desk Lamp | G8: 3 | H8: 5130 | I8: 0.05 | J8: 1024.86
A9: ORD008 | B9: 46038 | C9: Fatima | D9: South | E9: Electronics | F9: Mouse | G9: 1 | H9: 950 | I9: 0.05 | J9: 215.94
A10: ORD009 | B10: 46124 | C10: Priya | D10: West | E10: Electronics | F10: Headphones | G10: 2 | H10: 5400 | I10: 0.1 | J10: 758.14
A11: ORD010 | B11: 46198 | C11: Priya | D11: North | E11: Furniture | F11: Desk Lamp | G11: 2 | H11: 3420 | I11: 0.05 | J11: 368.6
A12: ORD011 | B12: 46124 | C12: Priya | D12: South | E12: Electronics | F12: Headphones | G12: 1 | H12: 2850 | I12: 0.05 | J12: 626.16
A13: ORD012 | B13: 46107 | C13: Ananya | D13: East | E13: electronics | F13: Smartphone | G13: 2 | H13: 57600 | I13: 0.1 | J13: 6690.04
... A19: ORD018 | B19: 46164 | C19: Sneha | D19: East | E19: Electronics | F19: Headphones | G19: 1 | H19: 2700 | I19: 0.1 | J19: 415.56
A20: ORD019 | B20: 46143 | D20: East | E20: Furniture | F20: Bookshelf | G20: 2 | H20: 14000 | I20: 0 | J20: 3191.83
A21: ORD020 | B21: 46103 | C21: Aditya | D21: South | E21: Electronics | F21: Monitor | G21: 3 | H21: 42750 | I21: 0.05 | J21: 7339.94
A22: ORD021 | B22: 46162 | C22: Zoya | D22: North | E22: Furniture | F22: Desk Lamp | G22: 3 | H22: 4590 | I22: 0.15 | J22: 382.4
A23: ORD022 | B23: 46119 | C23: Zoya | D23: East | E23: Electronics | F23: Keyboard | G23: 1 | H23: 2375 | I23: 0.05 | J23: 544.5
A24: ORD023 | B24: 46047 | C24: Rahul | E24: Electronics | F24: Smartphone | G24: 5 | H24: 152000 | I24: 0.05 | J24: 15477.64
A25: ORD024 | B25: 46148 | C25: Neha | D25: South | E25: Electronics | F25: Mouse | G25: 5 | H25: 4250 | I25: 0.15 | J25: 1036.75
A26: ORD025 | B26: 46165 | C26: Sneha | D26: South | E26: Electronics | F26: Mouse | G26: 4 | H26: 3600 | I26: 0.1 | J26: 556.12
A27: ORD026 | B27: 46159 | C27: Vikram | D27: North | E27: Electronics | F27: Keyboard | G27: 2 | H27: 5000 | I27: 0 | J27: 687.37
A28: ORD027 | B28: 46177 | C28: Neha | D28: South | E28: Furniture | F28: Desk Lamp | G28: 2 | H28: 3600 | I28: 0 | J28: 331.45
A29: ORD028 | B29: 46188 | C29: Neha | D29: South | E29: Electronics | F29: Smartphone | G29: 1 | H29: 28800 | I29: 0.1 | J29: 2650.92
A30: ORD029 | B30: 46087 | C30: Priya | D30: West | E30: Electronics | F30: Keyboard | G30: 5 | H30: 11875 | I30: 0.05 | J30: 2410.27
A31: ORD030 | B31: 46173 | C31: Rohan | D31: West | E31: Electronics | F31: Keyboard | G31: 4 | H31: 8500 | I31: 0.15 | J31: 955.14
A32: ORD031 | B32: 46051 | C32: Fatima | D32: West | E32: Electronics | F32: Headphones | G32: 4 | H32: 10200 | I32: 0.15 | J32: 1625.82
A33: ORD032 | B33: 46040 | C33: Fatima | D33: North | E33: Furniture | F33: Laptop | G33: 4 | H33: 198000 | I33: 0.1 | J33: 42787.94
A34: ORD033 | B34: 46054 | C34: Arjun | D34: South | E34: Electronics | F34: Keyboard | G34: 5 | H34: 10625 | I34: 0.15 | J34: 1103.2
A35: ORD034 | B35: 46073 | C35: Priya | D35: West | E35: Electronics | F35: Keyboard | G35: 1 | H35: 2125 | I35: 0.15 | J35: 461.9
A36: ORD035 | B36: 46167 | C36: Rahul | D36: North | E36: Furniture | F36: Bookshelf | G36: 1 | H36: 7000 | I36: 0 | J36: 1662.38
... A39: ORD038 | B39: 46143 | C39: Priya | D39: West | E39: Furniture | F39: Bookshelf | G39: 4 | H39: 26600 | I39: 0.05 | J39: 2986.72
A40: ORD039 | B40: 46082 | C40: Aisha | D40: North | E40: Electronics | F40: Headphones | G40: 1 | I40: 0 | J40: 537.93
A41: ORD040 | B41: 46155 | C41: Zoya | D41: South | E41: Electronics | F41: Laptop | G41: 5 | H41: 275000 | I41: 0 | J41: 61800.26
A42: ORD041 | B42: 46044 | D42: North | E42: Electronics | F42: Keyboard | G42: 4 | H42: 10000 | I42: 0 | J42: 2400.71
A43: ORD042 | B43: 46172 | C43: Arjun | D43: North | E43: Furniture | F43: Desk Lamp | G43: 1 | H43: 1530 | I43: 0.15 | J43: 293.38
A44: ORD043 | B44: 46171 | C44: Neha | D44: East | E44: Electronics | F44: Mouse | G44: 2 | H44: 1800 | I44: 0.1 | J44: 217.04
A45: ORD044 | B45: 46128 | C45: Sara | D45: East | E45: Furniture | F45: Study Table | G45: 3 | H45: 36000 | I45: 0 | J45: 2937.01
A46: ORD045 | B46: 46186 | C46: Rohan | D46: NORTH | E46: Electronics | F46: Smartphone | G46: 5 | H46: 152000 | I46: 0.05 | J46: 25232.06
A47: ORD046 | B47: 46060 | C47: Zoya | D47: East | E47: Electronics | F47: Smartphone | G47: 2 | H47: 57600 | I47: 0.1 | J47: 7398.6
...

Sheet Project_Guide
A1: E-Commerce Sales & Profit Analysis
A3: Project workflow
A4: 1. Raw_Data → inspect and identify data-quality problems
A5: 2. Cleaned_Data → remove duplicates, clean text, handle blanks/errors
A6: 3. Analysis → formulas, lookups, date analysis and business classifications
A7: 4. PivotTables → category, region, product and monthly analysis
A8: 5. Charts → column, bar, line, pie/donut and combo charts
A9: 6. Dashboard → KPIs, charts, slicers and business insights
A10: 7. GitHub → README, screenshots and final Excel workbook
A13: Important
A14: Do not modify Raw_Data. Treat it as the original source file.
A15: We will build every other sheet step-by-step.

Sheet Cleaned_Data
A1: Order ID | B1: Order Date | C1: Customer | D1: Region | E1: Category | F1: Product | G1: Quantity | H1: Sales | I1: Discount | J1: Profit
A2: ORD001 | B2: 46190 | C2: Rahul | D2: North | E2: Electronics | F2: Mouse | G2: 2 | H2: 1900 | I2: 0.05 | J2: 197.07
A3: ORD002 | B3: 46053 | C3: Fatima | D3: North | E3: Furniture | F3: Desk Lamp | G3: 4 | H3: 7200 | I3: 0 | J3: 612.47
A4: ORD003 | B4: 46082 | C4: Arjun | D4: North | E4: Furniture | F4: Bookshelf | G4: 2 | H4: 11900 | I4: 0.15 | J4: 1397.95
A5: ORD004 | B5: 46177 | C5: Priya | D5: North | E5: Electronics | F5: Monitor | G5: 4 | H5: 54000 | I5: 0.1 | J5: 6870.86
A6: ORD005 | B6: 46082 | C6: Sneha | D6: South | E6: Electronics | F6: Smartphone | G6: 1 | H6: 27200 | I6: 0.15 | J6: 2623.22
A7: ORD006 | B7: 46115 | C7: Rohan | D7: East | E7: Electronics | F7: Laptop | G7: 4 | H7: 220000 | I7: 0 | J7: 53994.53
A8: ORD007 | B8: 46123 | C8: Rahul | D8: East | E8: Furniture | F8: Desk Lamp | G8: 3 | H8: 5130 | I8: 0.05 | J8: 1024.86
A9: ORD008 | B9: 46038 | C9: Fatima | D9: South | E9: Electronics | F9: Mouse | G9: 1 | H9: 950 | I9: 0.05 | J9: 215.94
A10: ORD009 | B10: 46124 | C10: Priya | D10: West | E10: Electronics | F10: Headphones | G10: 2 | H10: 5400 | I10: 0.1 | J10: 758.14
A11: ORD010 | B11: 46198 | C11: Priya | D11: North | E11: Furniture | F11: Desk Lamp | G11: 2 | H11: 3420 | I11: 0.05 | J11: 368.6
A12: ORD011 | B12: 46124 | C12: Priya | D12: South | E12: Electronics | F12: Headphones | G12: 1 | H12: 2850 | I12: 0.05 | J12: 626.16
A13: ORD012 | B13: 46107 | C13: Ananya | D13: East | E13: Electronics | F13: Smartphone | G13: 2 | H13: 57600 | I13: 0.1 | J13: 6690.04
... A51: ORD050 | B51: 46079 | C51: Fatima | D51: East | E51: Furniture | F51: Bookshelf | G51: 4 | H51: 25200 | I51: 0.1 | J51: 5894.46

Sheet Analysis
A1: Metric | B1: Value
A2: Total Sales | B2: =SUM(Cleaned_Data!H2:H51) -> 1897020
A3: Total Profit | B3: =SUM(Cleaned_Data!J2:J51) -> 341238.71
A4: Average Sales | B4: =AVERAGE(Cleaned_Data!H2:H51) -> 37940.4
A5: Total Orders | B5: =COUNTA(Cleaned_Data!A2:A51) -> 50
A6: Highest Sale | B6: =MAX(Cleaned_Data!H2:H51) -> 275000
A7: Total Quantity Sold | B7: =SUM(Cleaned_Data!G2:G51) -> 143
A8: Average Discount | B8: =AVERAGE(Cleaned_Data!I2:I51) -> 0.069
A11: Product | B11: Total Sales | C11: Total Profit | D11: Quantity Sold | F11: {=_xlfn._xlws.SORT(A12:D20,2,-1)} -> Laptop | G11: 892530 | H11: 205830.99 | I11: 18
A12: {=_xlfn.UNIQUE(Cleaned_Data!F2:F51)} -> Mouse | B12: =SUMIF(Cleaned_Data!F$2:F$51,A12,Cleaned_Data!H$2:H$51) -> 62850 | C12: =SUMIF(Cleaned_Data!F$2:F$51,A12,Cleaned_Data!J$2:J$51) -> 13533.16 | D12: =SUMIF(Cleaned_Data!F$2:F$51,A12,Cleaned_Data!G$2:G$51) -> 23 | F12: Smartphone | G12: 507200 | H12: 63463.94 | I12: 17
A13: Desk Lamp | B13: =SUMIF(Cleaned_Data!F$2:F$51,A13,Cleaned_Data!H$2:H$51) -> 40590 | C13: =SUMIF(Cleaned_Data!F$2:F$51,A13,Cleaned_Data!J$2:J$51) -> 5621.21 | D13: =SUMIF(Cleaned_Data!F$2:F$51,A13,Cleaned_Data!G$2:G$51) -> 24 | F13: Monitor | G13: 184500 | H13: 20821.12 | I13: 13
A14: Bookshelf | B14: =SUMIF(Cleaned_Data!F$2:F$51,A14,Cleaned_Data!H$2:H$51) -> 91700 | C14: =SUMIF(Cleaned_Data!F$2:F$51,A14,Cleaned_Data!J$2:J$51) -> 16504.58 | D14: =SUMIF(Cleaned_Data!F$2:F$51,A14,Cleaned_Data!G$2:G$51) -> 14 | F14: Bookshelf | G14: 91700 | H14: 16504.58 | I14: 14
A15: Monitor | B15: =SUMIF(Cleaned_Data!F$2:F$51,A15,Cleaned_Data!H$2:H$51) -> 184500 | C15: =SUMIF(Cleaned_Data!F$2:F$51,A15,Cleaned_Data!J$2:J$51) -> 20821.12 | D15: =SUMIF(Cleaned_Data!F$2:F$51,A15,Cleaned_Data!G$2:G$51) -> 13 | F15: Mouse | G15: 62850 | H15: 13533.16 | I15: 23
A16: Smartphone | B16: =SUMIF(Cleaned_Data!F$2:F$51,A16,Cleaned_Data!H$2:H$51) -> 507200 | C16: =SUMIF(Cleaned_Data!F$2:F$51,A16,Cleaned_Data!J$2:J$51) -> 63463.94 | D16: =SUMIF(Cleaned_Data!F$2:F$51,A16,Cleaned_Data!G$2:G$51) -> 17 | F16: Keyboard | G16: 50500 | H16: 8563.09 | I16: 22
A17: Laptop | B17: =SUMIF(Cleaned_Data!F$2:F$51,A17,Cleaned_Data!H$2:H$51) -> 892530 | C17: =SUMIF(Cleaned_Data!F$2:F$51,A17,Cleaned_Data!J$2:J$51) -> 205830.99 | D17: =SUMIF(Cleaned_Data!F$2:F$51,A17,Cleaned_Data!G$2:G$51) -> 18 | F17: Desk Lamp | G17: 40590 | H17: 5621.21 | I17: 24
A18: Headphones | B18: =SUMIF(Cleaned_Data!F$2:F$51,A18,Cleaned_Data!H$2:H$51) -> 31150 | C18: =SUMIF(Cleaned_Data!F$2:F$51,A18,Cleaned_Data!J$2:J$51) -> 3963.61 | D18: =SUMIF(Cleaned_Data!F$2:F$51,A18,Cleaned_Data!G$2:G$51) -> 9 | F18: Study Table | G18: 36000 | H18: 2937.01 | I18: 3
A19: Keyboard | B19: =SUMIF(Cleaned_Data!F$2:F$51,A19,Cleaned_Data!H$2:H$51) -> 50500 | C19: =SUMIF(Cleaned_Data!F$2:F$51,A19,Cleaned_Data!J$2:J$51) -> 8563.09 | D19: =SUMIF(Cleaned_Data!F$2:F$51,A19,Cleaned_Data!G$2:G$51) -> 22 | F19: Headphones | G19: 31150 | H19: 3963.61 | I19: 9
A20: Study Table | B20: =SUMIF(Cleaned_Data!F$2:F$51,A20,Cleaned_Data!H$2:H$51) -> 36000 | C20: =SUMIF(Cleaned_Data!F$2:F$51,A20,Cleaned_Data!J$2:J$51) -> 2937.01 | D20: =SUMIF(Cleaned_Data!F$2:F$51,A20,Cleaned_Data!G$2:G$51) -> 3
F23: {=_xlfn.UNIQUE(Cleaned_Data!E2:E51)} -> Electronics | G23: =SUMIF(Cleaned_Data!E2:E51,F23,Cleaned_Data!H2:H51) -> 1483600 | H23: =SUMIF(Cleaned_Data!E2:E51,F23,Cleaned_Data!J2:J51) -> 262815.54
F24: Furniture | G24: =SUMIF(Cleaned_Data!E3:E52,F24,Cleaned_Data!H3:H52) -> 413420 | H24: =SUMIF(Cleaned_Data!E3:E52,F24,Cleaned_Data!J3:J52) -> 78423.17
F27: Region | G27: Total Sales | H27: Total Profit
F28: {=_xlfn.UNIQUE(_xlfn._xlws.FILTER(TRIM(Cleaned_Data!D2:D51),TRIM(Cleaned_Data!D2:D51)<>""))} -> North | G28: =SUMIF(Cleaned_Data!D2:D51,F28,Cleaned_Data!H2:H51) -> 359540 | H28: =SUMIF(Cleaned_Data!D2:D51,F28,Cleaned_Data!J2:J51) -> 59597.01
F29: South | G29: =SUMIF(Cleaned_Data!D3:D52,F29,Cleaned_Data!H3:H52) -> 398675 | H29: =SUMIF(Cleaned_Data!D3:D52,F29,Cleaned_Data!J3:J52) -> 78068.02
F30: East | G30: =SUMIF(Cleaned_Data!D4:D53,F30,Cleaned_Data!H4:H53) -> 449275 | H30: =SUMIF(Cleaned_Data!D4:D53,F30,Cleaned_Data!J4:J53) -> 87247.19
F31: West | G31: =SUMIF(Cleaned_Data!D5:D54,F31,Cleaned_Data!H5:H54) -> 384580 | H31: =SUMIF(Cleaned_Data!D5:D54,F31,Cleaned_Data!J5:J54) -> 75400.85
F32: Unknown | G32: =SUMIF(Cleaned_Data!D6:D55,F32,Cleaned_Data!H6:H55) -> 152000 | H32: =SUMIF(Cleaned_Data!D6:D55,F32,Cleaned_Data!J6:J55) -> 15477.64
F35: Customer | G35: Total Sales | H35: Total Profit | J35: Customer | K35: Total Sales | L35: Total Profit
F36: {=_xlfn.UNIQUE(Cleaned_Data!C2:C51)} -> Rahul | G36: =SUMIF(Cleaned_Data!C2:C51,F36,Cleaned_Data!H2:H51) -> 166030 | H36: =SUMIF(Cleaned_Data!C2:C51,F36,Cleaned_Data!J2:J51) -> 18361.95 | J36: {=_xlfn._xlws.SORT(F36:H49,2,-1)} -> Rohan | K36: 380500 | L36: 80181.73
F37: Fatima | G37: =SUMIF(Cleaned_Data!C3:C52,F37,Cleaned_Data!H3:H52) -> 241550 | H37: =SUMIF(Cleaned_Data!C3:C52,F37,Cleaned_Data!J3:J52) -> 51136.63 | J37: Zoya | K37: 339565 | L37: 70125.76
F38: Arjun | G38: =SUMIF(Cleaned_Data!C4:C53,F38,Cleaned_Data!H4:H53) -> 24055 | H38: =SUMIF(Cleaned_Data!C4:C53,F38,Cleaned_Data!J4:J53) -> 2794.53 | J38: Sara | K38: 284350 | L38: 61273.85
F39: Priya | G39: =SUMIF(Cleaned_Data!C5:C54,F39,Cleaned_Data!H5:H54) -> 151270 | H39: =SUMIF(Cleaned_Data!C5:C54,F39,Cleaned_Data!J5:J54) -> 15880.6 | J39: Fatima | K39: 241550 | L39: 51136.63
F40: Sneha | G40: =SUMIF(Cleaned_Data!C6:C55,F40,Cleaned_Data!H6:H55) -> 35030 | H40: =SUMIF(Cleaned_Data!C6:C55,F40,Cleaned_Data!J6:J55) -> 3816.56 | J40: Rahul | K40: 166030 | L40: 18361.95
F41: Rohan | G41: =SUMIF(Cleaned_Data!C7:C56,F41,Cleaned_Data!H7:H56) -> 380500 | H41: =SUMIF(Cleaned_Data!C7:C56,F41,Cleaned_Data!J7:J56) -> 80181.73 | J41: Priya | K41: 151270 | L41: 15880.6
F42: Ananya | G42: =SUMIF(Cleaned_Data!C8:C57,F42,Cleaned_Data!H8:H57) -> 100350 | H42: =SUMIF(Cleaned_Data!C8:C57,F42,Cleaned_Data!J8:J57) -> 11902.41 | J42: Ananya | K42: 100350 | L42: 11902.41
F43: Neha | G43: =SUMIF(Cleaned_Data!C9:C58,F43,Cleaned_Data!H9:H58) -> 83570 | H43: =SUMIF(Cleaned_Data!C9:C58,F43,Cleaned_Data!J9:J58) -> 9865.08 | J43: Neha | K43: 83570 | L43: 9865.08
F44: Unknown | G44: =SUMIF(Cleaned_Data!C10:C59,F44,Cleaned_Data!H10:H59) -> 24000 | H44: =SUMIF(Cleaned_Data!C10:C59,F44,Cleaned_Data!J10:J59) -> 5592.54 | J44: Aditya | K44: 51750 | L44: 9081.77
F45: Aditya | G45: =SUMIF(Cleaned_Data!C11:C60,F45,Cleaned_Data!H11:H60) -> 51750 | H45: =SUMIF(Cleaned_Data!C11:C60,F45,Cleaned_Data!J11:J60) -> 9081.77 | J45: Sneha | K45: 35030 | L45: 3816.56
F46: Zoya | G46: =SUMIF(Cleaned_Data!C12:C61,F46,Cleaned_Data!H12:H61) -> 339565 | H46: =SUMIF(Cleaned_Data!C12:C61,F46,Cleaned_Data!J12:J61) -> 70125.76 | J46: Arjun | K46: 24055 | L46: 2794.53
F47: Vikram | G47: =SUMIF(Cleaned_Data!C13:C62,F47,Cleaned_Data!H13:H62) -> 5000 | H47: =SUMIF(Cleaned_Data!C13:C62,F47,Cleaned_Data!J13:J62) -> 687.37 | J47: Unknown | K47: 24000 | L47: 5592.54
F48: Sara | G48: =SUMIF(Cleaned_Data!C14:C63,F48,Cleaned_Data!H14:H63) -> 284350 | H48: =SUMIF(Cleaned_Data!C14:C63,F48,Cleaned_Data!J14:J63) -> 61273.85 | J48: Aisha | K48: 10000 | L48: 537.93
...

Sheet Dashboard
A1: E-Commerce Sales Analysis Dashboard
A3: Business Performance Overview
A6: Total Sales | C6: Total Profit | E6: Total Orders | G6: Average Order Value
A7: =SUM(Cleaned_Data!H2:H51) -> 1897020 | C7: =SUM(Cleaned_Data!J2:J51) -> 341238.71 | E7: =COUNTA(Cleaned_Data!A2:A51) -> 50 | G7: =AVERAGE(Cleaned_Data!H2:H51) -> 37940.4
A86: Insights:
A88: Total Sales: ₹18,97,020
A90: Total Profit: ₹3,41,238.71
A92: Total Orders: 50
A94: Average Order Value: ₹37,940.40
A96: Laptop contributes the highest product sales.
A98: Electronics contributes substantially more sales than Furniture.
A100: East region has the highest sales and profit among the listed regions.
A102: May has the highest number of orders.
